Workbook

Sheet Tabela 1
A1: Metoda ekspansji | G1: Metoda Fibonacciego | K1: Metoda oparta na inperpolacji Lagrange'a
A2: Współczynnik ekspansji | B2: Lp. | C2: x(0) | D2: a | E2: b | F2: Liczba wywołań funkcji celu | G2: x* | H2: y* | I2: Liczba wywołań funkcji celu | J2: Minimum lokalne/globalne | K2: x* | L2: y* | M2: Liczba wywołań funkcji celu | N2: Minimum lokalne/globalne
A3: 1.283001 | B3: 1 | C3: 13.98 | D3: -5.914084 | E3: 1.894352 | F3: 16 | G3: -0.004356 | H3: 0 | I3: 25 | J3: loc | K3: 0.006062 | L3: 0 | M3: 12 | N3: loc
B4: 2 | C4: 31.57 | D4: -10.445054 | E4: 6.045871 | F4: 18 | G4: 0.002177 | H4: 0 | I4: 29 | J4: loc | K4: -13.010934 | L4: 0.003386 | M4: 13 | N4: brak
B5: 3 | C5: -45.74 | D5: -12.992517 | E5: 8.165356 | F5: 18 | G5: 0.001889 | H5: 0 | I5: 29 | J5: loc | K5: -12.783619 | L5: 0.003268 | M5: 13 | N5: brak
B6: 4 | C6: 91.03 | D6: 58.282517 | E6: 71.135916 | F6: 17 | G6: 62.741367 | H6: -0.921148 | I6: 27 | J6: glob | K6: -347.10038 | L6: 2.409574 | M6: 5 | N6: brak
B7: 5 | C7: -14.44 | D7: -2.354352 | E7: 5.454084 | F7: 14 | G7: -0.004701 | H7: 0 | I7: 25 | J7: loc | K7: -0.41161 | L7: 3e-06 | M7: 13 | N7: loc
B8: 6 | C8: -51.46 | D8: -9.444946 | E8: 17.700626 | F8: 19 | G8: -0.004702 | H8: 0 | I8: 31 | J8: loc | K8: -1.735612 | L8: 6e-05 | M8: 13 | N8: brak
B9: 7 | C9: -76.44 | D9: -22.534644 | E9: 12.293152 | F9: 20 | G9: -0.001951 | H9: 0 | I9: 31 | J9: loc | K9: -5.672365 | L9: 0.000644 | M9: 13 | N9: brak
B10: 8 | C10: -57.51 | D10: -15.494946 | E10: 11.650626 | F10: 19 | G10: -0.003596 | H10: 0 | I10: 31 | J10: loc | K10: -20.884443 | L10: 0.008723 | M10: 13 | N10: brak
B11: 9 | C11: -23.87 | D11: -3.975916 | E11: 8.877483 | F11: 16 | G11: -0.008023 | H11: 0 | I11: 27 | J11: loc | K11: -1.54461 | L11: 4.8e-05 | M11: 13 | N11: brak
B12: 10 | C12: -42.35 | D12: -9.602517 | E12: 11.555356 | F12: 18 | G12: 0.002044 | H12: 0 | I12: 29 | J12: loc | K12: -0.014937 | L12: 0 | M12: 10 | N12: loc
B13: 11 | C13: 46.93 | D13: 59.015648 | E13: 66.824084 | F13: 14 | G13: 62.749773 | H13: -0.921148 | I13: 25 | J13: glob | K13: -1213.2085 | L13: 29.437496 | M13: 5 | N13: brak
B14: 12 | C14: -14.46 | D14: -2.374352 | E14: 5.434084 | F14: 14 | G14: -0.000967 | H14: 0 | I14: 25 | J14: loc | K14: -0.362321 | L14: 3e-06 | M14: 13 | N14: loc
B15: 13 | C15: -99.09 | D15: -29.929374 | E15: 14.754722 | F15: 21 | G15: -0.007873 | H15: 0 | I15: 33 | J15: loc | K15: -3.739235 | L15: 0.00028 | M15: 13 | N15: brak
... B28: 26 | C28: -39.46 | D28: -6.712517 | E28: 14.445356 | F28: 18 | G28: 0.001669 | H28: 0 | I28: 29 | J28: loc | K28: -1.437855 | L28: 4.1e-05 | M28: 13 | N28: brak
B29: 27 | C29: 61.81 | D29: 62.81 | E29: 63.093001 | F29: 3 | G29: 62.818324 | H29: -0.921074 | I29: 11 | J29: glob | K29: -21532516 | L29: 9272984733,520845 | M29: 5 | N29: brak
B30: 28 | C30: -57.75 | D30: -15.734946 | E30: 11.410626 | F30: 19 | G30: -0.00337 | H30: 0 | I30: 31 | J30: loc | K30: -17.271977 | L30: 0.005966 | M30: 13 | N30: brak
B31: 29 | C31: -32.11 | D31: -6.585871 | E31: 9.905054 | F31: 17 | G31: 0.000288 | H31: 0 | I31: 29 | J31: loc | K31: -1.461285 | L31: 4.3e-05 | M31: 13 | N31: brak
B32: 30 | C32: -94.36 | D32: -25.199374 | E32: 19.484722 | F32: 21 | G32: -0.000582 | H32: 0 | I32: 33 | J32: loc | K32: -15.147676 | L32: 0.004589 | M32: 13 | N32: brak
B33: 31 | C33: -68.24 | D33: -14.334644 | E33: 20.493152 | F33: 20 | G33: 0.001313 | H33: 0 | I33: 31 | J33: loc | K33: -3.812777 | L33: 0.000291 | M33: 13 | N33: brak
B34: 32 | C34: -1.86 | D34: -0.576999 | E34: 0.251937 | F34: 5 | G34: -0.008852 | H34: 0 | I34: 15 | J34: loc | K34: -11.309857 | L34: 0.002558 | M34: 8 | N34: brak
B35: 33 | C35: 80.1 | D35: 60.205916 | E35: 68.014352 | F35: 15 | G35: 62.745438 | H35: -0.921148 | I35: 25 | J35: glob | K35: -1305.582 | L35: 34.090888 | M35: 5 | N35: brak
B36: 34 | C36: -80.64 | D36: -11.479374 | E36: 33.204722 | F36: 21 | G36: -0.006163 | H36: 0 | I36: 33 | J36: loc | K36: 3.467786 | L36: 0.000241 | M36: 13 | N36: brak
B37: 35 | C37: -15.62 | D37: -3.534352 | E37: 4.274084 | F37: 14 | G37: -0.00592 | H37: 0 | I37: 25 | J37: loc | K37: 0.009349 | L37: 0 | M37: 7 | N37: loc
B38: 36 | C38: -76.01 | D38: -22.104644 | E38: 12.723152 | F38: 20 | G38: -0.005112 | H38: 0 | I38: 31 | J38: loc | K38: -6.318147 | L38: 0.000798 | M38: 13 | N38: brak
B39: 37 | C39: -56.42 | D39: -14.404946 | E39: 12.740626 | F39: 19 | G39: -0.004354 | H39: 0 | I39: 31 | J39: loc | K39: 0.00552 | L39: 0 | M39: 12 | N39: loc
B40: 38 | C40: -36.71 | D40: -11.185871 | E40: 5.305054 | F40: 17 | G40: -0.004718 | H40: 0 | I40: 29 | J40: loc | K40: -9.34141 | L40: 0.001745 | M40: 13 | N40: brak
B41: 39 | C41: 25.38 | D41: -7.367483 | E41: 5.485916 | F41: 17 | G41: -0.003137 | H41: 0 | I41: 27 | J41: loc | K41: -39.562218 | L41: 0.031303 | M41: 13 | N41: brak
... B102: 100 | C102: 45.31 | D102: 57.395648 | E102: 65.204084 | F102: 14 | G102: 62.743675 | H102: -0.921148 | I102: 25 | J102: glob | K102: -1226.9977 | L102: 30.110468 | M102: 5 | N102: brak
A103: 1.170001 | B103: 1 | C103: -30.14 | D103: -3.105964 | E103: 6.866955 | F103: 26 | G103: -0.008551 | H103: 0 | I103: 27 | J103: loc | K103: -1.110438 | L103: 2.5e-05 | M103: 13 | N103: brak
B104: 2 | C104: 23.4 | D104: -3.634036 | E104: 3.651304 | F104: 24 | G104: -0.009819 | H104: 0 | I104: 25 | J104: loc | K104: 4e-06 | L104: 0 | M104: 7 | N104: loc
B105: 3 | C105: 30.77 | D105: -6.236955 | E105: 3.735964 | F105: 26 | G105: -0.004662 | H105: 0 | I105: 27 | J105: loc | K105: -21.223251 | L105: 0.009009 | M105: 13 | N105: brak
B106: 4 | C106: -7.18 | D106: -0.599865 | E106: 1.827562 | F106: 16 | G106: -0.001057 | H106: 0 | I106: 21 | J106: loc | K106: -0.149877 | L106: 0 | M106: 10 | N106: loc
B107: 5 | C107: -35.71 | D107: -4.080151 | E107: 7.588175 | F107: 26 | G107: -0.003178 | H107: 0 | I107: 27 | J107: loc | K107: -1.155992 | L107: 2.7e-05 | M107: 13 | N107: brak
B108: 6 | C108: -61.62 | D108: -10.961092 | E108: 7.727098 | F108: 29 | G108: 0.003032 | H108: 0 | I108: 29 | J108: loc | K108: -21.626139 | L108: 0.009354 | M108: 13 | N108: brak
B109: 7 | C109: -31 | D109: -3.965964 | E109: 6.006955 | F109: 25 | G109: -0.000526 | H109: 0 | I109: 27 | J109: loc | K109: -0.035355 | L109: 0 | M109: 10 | N109: loc
B110: 8 | C110: 54.77 | D110: 61.350135 | E110: 63.777562 | F110: 16 | G110: 62.740915 | H110: -0.921148 | I110: 21 | J110: glob | K110: -35243.746 | L110: 24842.433 | M110: 5 | N110: brak
B111: 9 | C111: -63.61 | D111: -12.951092 | E111: 5.737098 | F111: 29 | G111: 0.001906 | H111: 0 | I111: 29 | J111: loc | K111: -7.806679 | L111: 0.001219 | M111: 13 | N111: brak
B112: 10 | C112: 27.49 | D112: -4.139849 | E112: 4.384006 | F112: 25 | G112: -0.011782 | H112: 0 | I112: 25 | J112: loc | K112: 0.000829 | L112: 0 | M112: 7 | N112: loc
...

Sheet Tabela 2
A1: Współczynnik ekspansji | B1: Metoda ekspansji | D1: Rodzaj minimum | E1: Metoda Fibonacciego | I1: Metoda oparta na inperpolacji Lagrange'a
B2: b-a | C2: Liczba wywołań funkcji celu | E2: x* | F2: y* | G2: Liczba wywołań funkcji celu | H2: Liczba wystąpień | I2: x* | J2: y* | K2: Liczba wywołań funkcji celu | L2: Liczba wystąpień
A3: 1.20000 | B3: =AVERAGE('Tabela 1'!E$3:E$102) - AVERAGE('Tabela 1'!D$3:D$102) -> 17.945173 | C3: =AVERAGE('Tabela 1'!F3:F102) -> 15.93 | D3: Minimum globalne | E3: =AVERAGEIF('Tabela 1'!$J$3:$J$102,"glob",'Tabela 1'!G$3:G$102) -> 62.736838 | F3: =AVERAGEIF('Tabela 1'!$J$3:$J$102,"glob",'Tabela 1'!H$3:H$102) -> -0.92110825 | G3: =AVERAGEIF('Tabela 1'!$J$3:$J$102,"glob",'Tabela 1'!I$3:I$102) -> 23.5 | H3: =COUNTIF('Tabela 1'!J$3:J$102,"glob") -> 16 | I3: =IF(L3>0,AVERAGEIF('Tabela 1'!$N$3:$N$102,"glob",'Tabela 1'!K$3:K$102),"brak") -> brak | J3: =IF(M3>0,AVERAGEIF('Tabela 1'!$N$3:$N$102,"glob",'Tabela 1'!L$3:L$102),"brak") -> brak | K3: =IF(N3>0,AVERAGEIF('Tabela 1'!$N$3:$N$102,"glob",'Tabela 1'!M$3:M$102),"brak") -> brak | L3: =COUNTIF('Tabela 1'!N$3:N$102,"glob") -> 0
D4: Minimum lokalne | E4: =AVERAGEIF('Tabela 1'!$J$3:$J$102,"loc",'Tabela 1'!G$3:G$102) -> -0.0063815238 | F4: =AVERAGEIF('Tabela 1'!$J$3:$J$102,"loc",'Tabela 1'!H$3:H$102) -> 8.3333333e-08 | G4: =AVERAGEIF('Tabela 1'!$J$3:$J$102,"loc",'Tabela 1'!I$3:I$102) -> 27.452381 | H4: =COUNTIF('Tabela 1'!J$3:J$102,"loc") -> 84 | I4: =AVERAGEIF('Tabela 1'!$N$3:$N$102,"loc",'Tabela 1'!K$3:K$102) -> -0.078079333 | J4: =AVERAGEIF('Tabela 1'!$N$3:$N$102,"loc",'Tabela 1'!L$3:L$102) -> 3.9393939e-07 | K4: =AVERAGEIF('Tabela 1'!$N$3:$N$102,"loc",'Tabela 1'!M$3:M$102) -> 9.7575758 | L4: =COUNTIF('Tabela 1'!N$3:N$102,"loc") -> 33
D5: Brak zbieżności | G5: =IF(H5>0,AVERAGEIF('Tabela 1'!$J$3:$J$102,"brak",'Tabela 1'!I$3:I$102),"brak") -> brak | H5: =COUNTIF('Tabela 1'!J$3:J$102,"brak") -> 0 | K5: =IF(L5>0,AVERAGEIF('Tabela 1'!$N$3:$N$102,"brak",'Tabela 1'!M$3:M$102),"brak") -> 10.940299 | L5: =COUNTIF('Tabela 1'!N$3:N$102,"brak") -> 67
A6: 1.50000 | B6: =AVERAGE('Tabela 1'!E$103:E$202) - AVERAGE('Tabela 1'!D$103:D$202) -> 12.057923 | C6: =AVERAGE('Tabela 1'!F$103:F$202) -> 24.48 | D6: Minimum globalne | E6: =AVERAGEIF('Tabela 1'!$J$103:$J$202,"glob",'Tabela 1'!G$103:G$202) -> 62.744512 | F6: =AVERAGEIF('Tabela 1'!$J$103:$J$202,"glob",'Tabela 1'!H$103:H$202) -> -0.92114794 | G6: =AVERAGEIF('Tabela 1'!$J$103:$J$202,"glob",'Tabela 1'!I$103:I$202) -> 23.555556 | H6: =COUNTIF('Tabela 1'!J$103:J$202,"glob") -> 18 | I6: =IF(L6>0,AVERAGEIF('Tabela 1'!$N$103:$N$202,"glob",'Tabela 1'!K$103:K$202),"brak") -> brak | J6: =IF(M6>0,AVERAGEIF('Tabela 1'!$N$103:$N$202,"glob",'Tabela 1'!L$103:L$202),"brak") -> brak | K6: =IF(N6>0,AVERAGEIF('Tabela 1'!$N$103:$N$202,"glob",'Tabela 1'!M$103:M$202),"brak") -> brak | L6: =COUNTIF('Tabela 1'!N$103:N$202,"glob") -> 0
D7: Minimum lokalne | E7: =AVERAGEIF('Tabela 1'!$J$103:$J$202,"loc",'Tabela 1'!G$103:G$202) -> -0.0044539146 | F7: =AVERAGEIF('Tabela 1'!$J$103:$J$202,"loc",'Tabela 1'!H$103:H$202) -> 0 | G7: =AVERAGEIF('Tabela 1'!$J$103:$J$202,"loc",'Tabela 1'!I$103:I$202) -> 26.097561 | H7: =COUNTIF('Tabela 1'!J$103:J$202,"loc") -> 82 | I7: =AVERAGEIF('Tabela 1'!$N$103:$N$202,"loc",'Tabela 1'!K$103:K$202) -> -0.078773591 | J7: =AVERAGEIF('Tabela 1'!$N$103:$N$202,"loc",'Tabela 1'!L$103:L$202) -> 1.0681818e-06 | K7: =AVERAGEIF('Tabela 1'!$N$103:$N$202,"loc",'Tabela 1'!M$103:M$202) -> 8.9772727 | L7: =COUNTIF('Tabela 1'!N$103:N$202,"loc") -> 44
D8: Brak zbieżności | G8: =IF(H8>0,AVERAGEIF('Tabela 1'!$J$103:$J$202,"brak",'Tabela 1'!I$103:I$202),"brak") -> brak | H8: =COUNTIF('Tabela 1'!J$103:J$202,"brak") -> 0 | I8: ] | K8: =IF(L8>0,AVERAGEIF('Tabela 1'!$N$103:$N$202,"brak",'Tabela 1'!M$103:M$202),"brak") -> 10.410714 | L8: =COUNTIF('Tabela 1'!N$103:N$202,"brak") -> 56
A9: 2.00000 | B9: =AVERAGE('Tabela 1'!E$203:E$302) - AVERAGE('Tabela 1'!D$203:D$302) -> 12.344872 | C9: =AVERAGE('Tabela 1'!F$203:F$302) -> 22.62 | D9: Minimum globalne | E9: =AVERAGEIF('Tabela 1'!$J$103:$J$202,"glob",'Tabela 1'!G$103:G$202) -> 62.744512 | F9: =AVERAGEIF('Tabela 1'!$J$103:$J$202,"glob",'Tabela 1'!H$103:H$202) -> -0.92114794 | G9: =AVERAGEIF('Tabela 1'!$J$103:$J$202,"glob",'Tabela 1'!I$103:I$202) -> 23.555556 | H9: =COUNTIF('Tabela 1'!J$203:J$302,"glob") -> 16 | I9: =IF(L9>0,AVERAGEIF('Tabela 1'!$N$202:$N$203,"glob",'Tabela 1'!K$103:K$202),"brak") -> brak | J9: =IF(M9>0,AVERAGEIF('Tabela 1'!$N$202:$N$203,"glob",'Tabela 1'!L$103:L$202),"brak") -> brak | K9: =IF(N9>0,AVERAGEIF('Tabela 1'!$N$202:$N$203,"glob",'Tabela 1'!M$103:M$202),"brak") -> brak | L9: =COUNTIF('Tabela 1'!N$203:N$302,"glob") -> 0
D10: Minimum lokalne | E10: =AVERAGEIF('Tabela 1'!$J$203:$J$302,"loc",'Tabela 1'!G$203:G$302) -> -0.00086644048 | F10: =AVERAGEIF('Tabela 1'!$J$203:$J$302,"loc",'Tabela 1'!H$203:H$302) -> 2.3809524e-08 | G10: =AVERAGEIF('Tabela 1'!$J$203:$J$302,"loc",'Tabela 1'!I$203:I$302) -> 25.857143 | H10: =COUNTIF('Tabela 1'!J$203:J$302,"loc") -> 84 | I10: =AVERAGEIF('Tabela 1'!$N$203:$N$302,"loc",'Tabela 1'!K$203:K$302) -> -0.035898194 | J10: =AVERAGEIF('Tabela 1'!$N$203:$N$302,"loc",'Tabela 1'!L$203:L$302) -> 3.3333333e-07 | K10: =AVERAGEIF('Tabela 1'!$N$203:$N$302,"loc",'Tabela 1'!M$203:M$302) -> 8.8888889 | L10: =COUNTIF('Tabela 1'!N$203:N$302,"loc") -> 36
D11: Brak zbieżności | G11: =IF(H11>0,AVERAGEIF('Tabela 1'!$J$103:$J$202,"brak",'Tabela 1'!I$103:I$202),"brak") -> brak | H11: =COUNTIF('Tabela 1'!J$203:J$302,"brak") -> 0 | K11: =IF(L11>0,AVERAGEIF('Tabela 1'!$N$203:$N$302,"brak",'Tabela 1'!M$203:M$302),"brak") -> 10.703125 | L11: =COUNTIF('Tabela 1'!N$203:N$302,"brak") -> 64

Sheet Wykres
A1: Nr iteracji | B1: b-a
B2: Metoda Fibonacciego | C2: Metoda oparta na inperpolacji Lagrange'a
A3: 1 | B3: 6.40994 | C3: 6.40994
A4: 2 | B4: 3.96156 | C4: 3.20497
A5: 3 | B5: 2.44838 | C5: 2.00602
A6: 4 | B6: 1.51319 | C6: 0.0220324
A7: 5 | B7: 0.935189
A8: 6 | B8: 0.577998
A9: 7 | B9: 0.35719
A10: 8 | B10: 0.220808
A11: 9 | B11: 0.136382
A12: 10 | B12: 0.0844267
A13: 11 | B13: 0.0519549
A14: 12 | B14: 0.0324718
A15: 13 | B15: 0.0194831

Sheet Tabela 3
A1: Metoda Fibonacciego | D1: Metoda oparta na inperpolacji Lagrange'a
A2: DA* | B2: y* | C2: Liczba wywołań funkcji celu | D2: DA* | E2: y* | F2: Liczba wywołań funkcji celu
A3: 0.407554 | B3: 10.908591 | C3: 19 | D3: 0.079887 | E3: 188.45929 | F3: 18
A4: 0.12

Sheet Symulacja
A1: t | B1: VA | D1: VB | F1: TB
B2: Fibonacci | C2: Lagrange | D2: Fibonacci | E2: Lagrange | F2: Fibonacci | G2: Lagrange
