Workbook

Sheet Tabela 1
A1: Parametr a | B1: Lp. | C1: x1(0) | D1: x2(0) | E1: Zewnętrzna funkcja kary | J1: Wewnętrzna funkcja kary
E2: x1* | F2: x2* | G2: r* | H2: y* | I2: Liczba wywołań funkcji celu | J2: x1* | K2: x2* | L2: r* | M2: y* | N2: Liczba wywołań funkcji celu
A3: 4 | B3: 1 | C3: 2.797 | D3: 2.429 | E3: 2.797 | F3: 2.429 | G3: 3.704491 | H3: 1.259737 | I3: 8 | J3: 2.797 | K3: 2.429 | L3: 3.704491 | M3: -0.144052 | N3: 7
B4: 2 | C4: 3.043 | D4: 1.796 | E4: 3.043 | F4: 2.296 | G4: 3.812016 | H4: 1.252865 | I4: 15 | J4: 3.543 | K4: 1.796 | L4: 3.972212 | M4: -0.185879 | N4: 14
B5: 3 | C5: 1.446 | D5: 3.052 | E5: 2.446 | F5: 3.052 | G5: 3.911217 | H5: 2.450657 | I5: 22 | J5: 1.446 | K5: 3.552 | L5: 3.835051 | M5: -0.166673 | N5: 14
B6: 4 | C6: 2.745 | D6: 2.784 | E6: 2.745 | F6: 2.784 | G6: 3.909691 | H6: 1.104172 | I6: 8 | J6: 2.745 | K6: 2.784 | L6: 3.909691 | M6: -0.177704 | N6: 7
B7: 5 | C7: 1.668 | D7: 3.526 | E7: 1.668 | F7: 3.526 | G7: 3.900628 | H7: 1.940073 | I7: 8 | J7: 1.668 | K7: 3.526 | L7: 3.900628 | M7: -0.176439 | N7: 7
B8: 6 | C8: 3.084 | D8: 1.597 | E8: 3.084 | F8: 2.097 | G8: 3.729405 | H8: 1.405308 | I8: 15 | J8: 3.584 | K8: 1.597 | L8: 3.923706 | M8: -0.179621 | N8: 14
B9: 7 | C9: 2.493 | D9: 2.292 | E9: 2.493 | F9: 2.792 | G9: 3.743035 | H9: 1.223732 | I9: 15 | J9: 2.993 | K9: 2.292 | L9: 3.76979 | M9: -0.155894 | N9: 14
B10: 8 | C10: 1.565 | D10: 1.653 | E10: 2.565 | F10: 2.653 | G10: 3.690208 | H10: 10.826346 | I10: 36 | J10: 1.565 | K10: 3.653 | L10: 3.974121 | M10: -0.186113 | N10: 35
B11: 9 | C11: 1.218 | D11: 1.001 | E11: 2.718 | F11: 2.501 | G11: 3.693579 | H11: 43.819219 | I11: 50 | J11: 3.718 | K11: 1.001 | L11: 3.850393 | M11: -0.169054 | N11: 42
B12: 10 | C12: 1.797 | D12: 2.172 | E12: 2.797 | F12: 2.672 | G12: 3.868177 | H12: 4.940623 | I12: 29 | J12: 2.297 | K12: 3.172 | L12: 3.916349 | M12: -0.178621 | N12: 27
B13: 11 | C13: 3.069 | D13: 2.339 | E13: 3.069 | F13: 2.339 | G13: 3.858715 | H13: 1.214499 | I13: 8 | J13: 3.069 | K13: 2.339 | L13: 3.858715 | M13: -0.170321 | N13: 7
B14: 12 | C14: 3.186 | D14: 2.398 | E14: 3.186 | F14: 2.398 | G14: 3.987606 | H14: 1.14213 | I14: 8 | J14: 3.186 | K14: 2.398 | L14: 3.987606 | M14: -0.187743 | N14: 7
B15: 13 | C15: 1.887 | D15: 2.793 | E15: 2.387 | F15: 2.793 | G15: 3.674047 | H15: 1.288428 | I15: 15 | J15: 1.887 | K15: 3.293 | L15: 3.795342 | M15: -0.16024 | N15: 14
... B102: 100 | C102: 2.344 | D102: 1.626 | E102: 2.844 | F102: 2.626 | G102: 3.870945 | H102: 4.952429 | I102: 29 | J102: 3.344 | K102: 2.126 | L102: 3.962602 | M102: -0.184685 | N102: 27
A103: 4.4934 | B103: 1 | C103: 2.146 | D103: 1.488 | E103: 3.146 | F103: 2.988 | G103: 4.338832 | H103: 16.899052 | I103: 43 | J103: 4.146 | K103: 1.488 | L103: 4.404936 | M103: -0.216373 | N103: 35
B104: 2 | C104: 1.444 | D104: 3.862 | E104: 1.944 | F104: 3.862 | G104: 4.323677 | H104: 1.394086 | I104: 15 | J104: 1.944 | K104: 3.862 | L104: 4.323677 | M104: -0.21403 | N104: 13
B105: 3 | C105: 3.432 | D105: 2.386 | E105: 3.432 | F105: 2.886 | G105: 4.484152 | H105: 0.88336 | I105: 15 | J105: 3.432 | K105: 2.886 | L105: 4.484152 | M105: -0.217224 | N105: 13
B106: 4 | C106: 2.09 | D106: 2.713 | E106: 3.09 | F106: 3.213 | G106: 4.457743 | H106: 3.940517 | I106: 29 | J106: 2.09 | K106: 3.713 | L106: 4.260806 | M106: -0.211171 | N106: 21
B107: 5 | C107: 2.765 | D107: 2.935 | E107: 3.265 | F107: 2.935 | G107: 4.390268 | H107: 0.899517 | I107: 15 | J107: 2.765 | K107: 3.435 | L107: 4.409586 | M107: -0.216461 | N107: 14
B108: 6 | C108: 1.526 | D108: 1.574 | E108: 3.026 | F108: 3.074 | G108: 4.313485 | H108: 34.190581 | I108: 50 | J108: 1.526 | K108: 4.074 | L108: 4.35042 | M108: -0.214968 | N108: 42
B109: 7 | C109: 1.406 | D109: 4.04 | E109: 1.906 | F109: 4.04 | G109: 4.467039 | H109: 1.423247 | I109: 15 | J109: 1.906 | K109: 4.04 | L109: 4.467039 | M109: -0.217158 | N109: 13
B110: 8 | C110: 2.413 | D110: 1.248 | E110: 2.913 | F110: 3.248 | G110: 4.36292 | H110: 16.874324 | I110: 43 | J110: 3.913 | K110: 1.748 | L110: 4.285682 | M110: -0.212413 | N110: 34
B111: 9 | C111: 1.52 | D111: 1.656 | E111: 3.02 | F111: 3.156 | G111: 4.36815 | H111: 33.597285 | I111: 50 | J111: 1.52 | K111: 4.156 | L111: 4.425239 | M111: -0.216724 | N111: 42
B112: 10 | C112: 1.629 | D112: 2.603 | E112: 3.129 | F112: 3.103 | G112: 4.406728 | H112: 8.163616 | I112: 36 | J112: 1.629 | K112: 4.103 | L112: 4.41455 | M112: -0.21655 | N112: 28
B113: 11 | C113: 1.058 | D113: 4.001 | E113: 1.558 | F113: 4.001 | G113: 4.293642 | H113: 2.182183 | I113: 15 | J113: 1.558 | K113: 4.001 | L113: 4.293642 | M113: -0.21278 | N113: 13
B114: 12 | C114: 1.541 | D114: 2.934 | E114: 3.041 | F114: 2.934 | G114: 4.22564 | H114: 4.275377 | I114: 29 | J114: 2.041 | K114: 3.934 | L114: 4.431934 | M114: -0.216819 | N114: 27
B115: 13 | C115: 4.25 | D115: 1.078 | E115: 4.25 | F115: 1.078 | G115: 4.384585 | H115: 14.286312 | I115: 8 | J115: 4.25 | K115: 1.078 | L115: 4.384585 | M115: -0.215927 | N115: 7
... B202: 100 | C202: 2.647 | D202: 2.522 | E202: 3.147 | F202: 3.022 | G202: 4.363037 | H202: 1.957653 | I202: 22 | J202: 3.647 | K202: 2.522 | L202: 4.434083 | M202: -0.216848 | N202: 21
A203: 5 | B203: 1 | C203: 4.134 | D203: 1.377 | E203: 4.134 | F203: 2.377 | G203: 4.768657 | H203: 2.161721 | I203: 22 | J203: 4.134 | K203: 1.877 | L203: 4.540164 | M203: -0.216998 | N203: 15
B204: 2 | C204: 2.34 | D204: 1.989 | E204: 3.34 | F204: 3.489 | G204: 4.829981 | H204: 14.458744 | I204: 43 | J204: 3.84 | K204: 2.489 | L204: 4.576103 | M204: -0.2165 | N204: 35
B205: 3 | C205: 1.037 | D205: 2.148 | E205: 3.537 | F205: 3.148 | G205: 4.735005 | H205: 60.383897 | I205: 57 | J205: 1.537 | K205: 4.148 | L205: 4.423604 | M205: -0.216699 | N205: 43
B206: 4 | C206: 1.567 | D206: 2.807 | E206: 3.567 | F206: 3.307 | G206: 4.864128 | H206: 14.353951 | I206: 43 | J206: 1.567 | K206: 4.307 | L206: 4.583202 | M206: -0.21637 | N206: 28
B207: 5 | C207: 1.83 | D207: 1.097 | E207: 3.33 | F207: 3.597 | G207: 4.901766 | H207: 114.51717 | I207: 64 | J207: 4.33 | K207: 1.097 | L207: 4.466801 | M207: -0.217156 | N207: 43
B208: 6 | C208: 3.128 | D208: 3.521 | E208: 3.128 | F208: 3.521 | G208: 4.709758 | H208: 0.811623 | I208: 8 | J208: 3.128 | K208: 3.521 | L208: 4.709758 | M208: -0.212324 | N208: 7
B209: 7 | C209: 1.222 | D209: 1.109 | E209: 3.222 | F209: 3.609 | G209: 4.837992 | H209: 234.53358 | I209: 71 | J209: 4.222 | K209: 1.609 | L209: 4.518204 | M209: -0.217167 | N209: 57
B210: 8 | C210: 2.326 | D210: 1.466 | E210: 3.326 | F210: 3.466 | G210: 4.803689 | H210: 29.271827 | I210: 50 | J210: 4.326 | K210: 1.466 | L210: 4.567651 | M210: -0.216642 | N210: 35
B211: 9 | C211: 1.232 | D211: 3.743 | E211: 3.232 | F211: 3.743 | G211: 4.945288 | H211: 7.025827 | I211: 36 | J211: 1.232 | K211: 4.243 | L211: 4.418243 | M211: -0.216613 | N211: 15
B212: 10 | C212: 2.598 | D212: 3.423 | E212: 3.598 | F212: 3.423 | G212: 4.966139 | H212: 1.631466 | I212: 22 | J212: 3.098 | K212: 3.423 | L212: 4.616767 | M212: -0.215612 | N212: 15
...

Sheet Tabela 2
A1: Parametr a | B1: Zewnętrzna funkcja kary | G1: Wewnętrzna funkcja kary
B2: x1* | C2: x2* | D2: r* | E2: y* | F2: Liczba wywołań funkcji celu | G2: x1* | H2: x2* | I2: r* | J2: y* | K2: Liczba wywołań funkcji celu
A3: 4 | B3: =AVERAGE('Tabela 1'!E$3:E$102) -> 2.68718 | C3: =AVERAGE('Tabela 1'!F3:F102) -> 2.64567 | D3: =AVERAGE('Tabela 1'!G3:G102) -> 3.8238568 | E3: =AVERAGE('Tabela 1'!H3:H102) -> 6.6496619 | F3: =AVERAGE('Tabela 1'!I3:I102) -> 21.37 | G3: =AVERAGE('Tabela 1'!J3:J102) -> 2.61718 | H3: =AVERAGE('Tabela 1'!K3:K102) -> 2.60067 | I3: =AVERAGE('Tabela 1'!L3:L102) -> 3.8696027 | J3: =AVERAGE('Tabela 1'!M3:M102) -> -0.17116038 | K3: =AVERAGE('Tabela 1'!N3:N102) -> 18.48
A4: 4.4934 | B4: =AVERAGE('Tabela 1'!E$103:E$202) -> 3.01086 | C4: =AVERAGE('Tabela 1'!F$103:F$202) -> 3.05064 | D4: =AVERAGE('Tabela 1'!G$103:G$202) -> 4.3402035 | E4: =AVERAGE('Tabela 1'!H$103:H$202) -> 8.042955 | F4: =AVERAGE('Tabela 1'!I$103:I$202) -> 26.2 | G4: =AVERAGE('Tabela 1'!J$103:J$202) -> 2.99586 | H4: =AVERAGE('Tabela 1'!K$103:K$202) -> 2.87064 | I4: =AVERAGE('Tabela 1'!L$103:L$202) -> 4.3902448 | ... K4: =AVERAGE('Tabela 1'!N$103:N$202) -> 22.03
A5: 5 | B5: =AVERAGE('Tabela 1'!E$203:E$302) -> 3.34454 | C5: =AVERAGE('Tabela 1'!F$203:F$302) -> 3.43756 | D5: =AVERAGE('Tabela 1'!G$203:G$302) -> 4.8590684 | E5: =AVERAGE('Tabela 1'!H$203:H$302) -> 24.320598 | F5: =AVERAGE('Tabela 1'!I$203:I$302) -> 32.28 | G5: =AVERAGE('Tabela 1'!J$203:J$302) -> 2.86954 | H5: =AVERAGE('Tabela 1'!K$203:K$302) -> 3.19256 | I5: =AVERAGE('Tabela 1'!L$203:L$302) -> 4.5635403 | ... K5: =AVERAGE('Tabela 1'!N$203:N$302) -> 21.78

Sheet Tabela 3
A1: v0x(0) | B1: ω(0) | C1: vox* | D1: ω* | E1: xend* | F1: Liczba wywołań funkcji celu
A2: 6.54134 | B2: -8.09912 | C2: 1.59675 | D2: -0.246853 | E2: 10.0285 | F2: 1220

Sheet Symulacja
A1: t | B1: x | C1: y
A2: 0 | B2: 0 | C2: 100
A3: 0.01 | B3: 0.0159648 | C3: 99.9995
A4: 0.02 | B4: 0.0319242 | C4: 99.998
A5: 0.03 | B5: 0.0478781 | C5: 99.9956
A6: 0.04 | B6: 0.0638267 | C6: 99.9922
A7: 0.05 | B7: 0.0797698 | C7: 99.9877
A8: 0.06 | B8: 0.0957076 | C8: 99.9823
A9: 0.07 | B9: 0.11164 | C9: 99.976
A10: 0.08 | B10: 0.127567 | C10: 99.9686
A11: 0.09 | B11: 0.143489 | C11: 99.9603
A12: 0.1 | B12: 0.159405 | C12: 99.951
A13: 0.11 | B13: 0.175316 | C13: 99.9407
... A702: 7 | B702: 10.0285 | C702: -17.8588
